<?xml version='1.0' encoding='ASCII'?>
<robot name="panda">
  <link name="panda_link0">
    <inertial>
      <origin xyz="-0.041018 -0.00014 0.049974" rpy="0.0 -0.0 0.0"/>
      <mass value="0.629769"/>
      <inertia ixx="0.00315" ixy="8.2904e-07" ixz="0.0015" iyy="0.00388" iyz="8.2299e-06" izz="0.004285"/>
    </inertial>
    <visual>
      <geometry>
        <mesh filename="panda_link0.obj"/>
      </geometry>
    </visual>
    <collision>
      <geometry>
        <mesh filename="panda_link0.obj"/>
      </geometry>
    </collision>
  </link>
  <link name="panda_link1">
    <inertial>
      <origin xyz="0.003875 0.002081 -0.04762" rpy="0.0 -0.0 0.0"/>
      <mass value="4.970684"/>
      <inertia ixx="0.70337" ixy="-0.000139" ixz="0.006772" iyy="0.70661" iyz="0.019169" izz="0.009117"/>
    </inertial>
    <visual>
      <geometry>
        <mesh filename="panda_link1.obj"/>
      </geometry>
    </visual>
    <collision>
      <geometry>
        <mesh filename="panda_link1.obj"/>
      </geometry>
    </collision>
  </link>
  <link name="panda_link2">
    <inertial>
      <origin xyz="-0.003141 -0.02872 0.003495" rpy="0.0 -0.0 0.0"/>
      <mass value="0.646926"/>
      <inertia ixx="0.007962" ixy="-0.003925" ixz="0.010254" iyy="0.02811" iyz="0.000704" izz="0.025995"/>
    </inertial>
    <visual>
      <geometry>
        <mesh filename="panda_link2.obj"/>
      </geometry>
    </visual>
    <collision>
      <geometry>
        <mesh filename="panda_link2.obj"/>
      </geometry>
    </collision>
  </link>
  <link name="panda_link3">
    <inertial>
      <origin xyz="0.027518 0.039252 -0.066502" rpy="0.0 -0.0 0.0"/>
      <mass value="3.228604"/>
      <inertia ixx="0.037242" ixy="-0.004761" ixz="-0.011396" iyy="0.036155" iyz="-0.012805" izz="0.01083"/>
    </inertial>
    <visual>
      <geometry>
        <mesh filename="panda_link3.obj"/>
      </geometry>
    </visual>
    <collision>
      <geometry>
        <mesh filename="panda_link3.obj"/>
      </geometry>
    </collision>
  </link>
  <link name="panda_link4">
    <inertial>
      <origin xyz="-0.05317 0.104419 0.027454" rpy="0.0 -0.0 0.0"/>
      <mass value="3.587895"/>
      <inertia ixx="0.025853" ixy="0.007796" ixz="-0.001332" iyy="0.019552" iyz="0.008641" izz="0.028323"/>
    </inertial>
    <visual>
      <geometry>
        <mesh filename="panda_link4.obj"/>
      </geometry>
    </visual>
    <collision>
      <geometry>
        <mesh filename="panda_link4.obj"/>
      </geometry>
    </collision>
  </link>
  <link name="panda_link5">
    <inertial>
      <origin xyz="-0.011953 0.041065 -0.038437" rpy="0.0 -0.0 0.0"/>
      <mass value="1.225946"/>
      <inertia ixx="0.035549" ixy="-0.002117" ixz="-0.004037" iyy="0.029474" iyz="0.000229" izz="0.008627"/>
    </inertial>
    <visual>
      <geometry>
        <mesh filename="panda_link5.obj"/>
      </geometry>
    </visual>
    <collision>
      <geometry>
        <mesh filename="panda_link5.obj"/>
      </geometry>
    </collision>
  </link>
  <link name="panda_link6">
    <inertial>
      <origin xyz="0.060149 -0.014117 -0.010517" rpy="0.0 -0.0 0.0"/>
      <mass value="1.666555"/>
      <inertia ixx="0.001964" ixy="0.000109" ixz="-0.001158" iyy="0.004354" iyz="0.000341" izz="0.005433"/>
    </inertial>
    <visual>
      <geometry>
        <mesh filename="panda_link6.obj"/>
      </geometry>
    </visual>
    <collision>
      <geometry>
        <mesh filename="panda_link6.obj"/>
      </geometry>
    </collision>
  </link>
  <link name="panda_link7">
    <inertial>
      <origin xyz="0.010517 -0.004252 0.061597" rpy="0.0 -0.0 0.0"/>
      <mass value="0.735522"/>
      <inertia ixx="0.012516" ixy="-0.000428" ixz="-0.001196" iyy="0.010027" iyz="-0.000741" izz="0.004815"/>
    </inertial>
    <visual>
      <geometry>
        <mesh filename="panda_link7.obj"/>
      </geometry>
    </visual>
    <collision>
      <geometry>
        <mesh filename="panda_link7.obj"/>
      </geometry>
    </collision>
  </link>
  <link name="panda_hand">
    <inertial>
      <origin xyz="-0.01 0.0 0.03" rpy="0.0 -0.0 0.0"/>
      <mass value="0.73"/>
      <inertia ixx="0.002477" ixy="-4.326e-07" ixz="9.807e-08" iyy="0.000498" iyz="-4.494e-05" izz="0.002242"/>
    </inertial>
  </link>
  <link name="panda_leftfinger">
    <inertial>
      <origin xyz="0.0 0.013756 0.024597" rpy="0.0 -0.0 0.0"/>
      <mass value="0.015"/>
      <inertia ixx="4.906e-06" ixy="3.271e-10" ixz="-1.975e-09" iyy="4.76e-06" iyz="9.483e-07" izz="1.151e-06"/>
    </inertial>
  </link>
  <link name="panda_rightfinger">
    <inertial>
      <origin xyz="0.0 -0.013756 0.024597" rpy="0.0 -0.0 0.0"/>
      <mass value="0.015"/>
      <inertia ixx="4.906e-06" ixy="3.271e-10" ixz="-1.975e-09" iyy="4.76e-06" iyz="9.483e-07" izz="1.151e-06"/>
    </inertial>
  </link>
  <link name="panda_tool"/>
  <joint name="panda_joint1" type="revolute">
    <parent link="panda_link0"/>
    <child link="panda_link1"/>
    <origin xyz="0.0 0.0 0.333" rpy="0.0 -0.0 0.0"/>
    <axis xyz="0.0 0.0 1.0"/>
    <limit effort="87.0" velocity="2.175" lower="-2.8973" upper="2.8973"/>
    <dynamics damping="10.0"/>
  </joint>
  <joint name="panda_joint2" type="revolute">
    <parent link="panda_link1"/>
    <child link="panda_link2"/>
    <origin xyz="0.0 0.0 0.0" rpy="-1.57079632679 -0.0 0.0"/>
    <axis xyz="0.0 0.0 1.0"/>
    <limit effort="87.0" velocity="2.175" lower="-1.7628" upper="1.7628"/>
    <dynamics damping="10.0"/>
  </joint>
  <joint name="panda_joint3" type="revolute">
    <parent link="panda_link2"/>
    <child link="panda_link3"/>
    <origin xyz="0.0 -0.316 0.0" rpy="1.57079632679 -0.0 0.0"/>
    <axis xyz="0.0 0.0 1.0"/>
    <limit effort="87.0" velocity="2.175" lower="-2.8973" upper="2.8973"/>
    <dynamics damping="10.0"/>
  </joint>
  <joint name="panda_joint4" type="revolute">
    <parent link="panda_link3"/>
    <child link="panda_link4"/>
    <origin xyz="0.0825 0.0 0.0" rpy="1.57079632679 -0.0 0.0"/>
    <axis xyz="0.0 0.0 1.0"/>
    <limit effort="87.0" velocity="2.175" lower="-3.0718" upper="-0.0698"/>
    <dynamics damping="10.0"/>
  </joint>
  <joint name="panda_joint5" type="revolute">
    <parent link="panda_link4"/>
    <child link="panda_link5"/>
    <origin xyz="-0.0825 0.384 0.0" rpy="-1.57079632679 -0.0 0.0"/>
    <axis xyz="0.0 0.0 1.0"/>
    <limit effort="12.0" velocity="2.61" lower="-2.8973" upper="2.8973"/>
    <dynamics damping="10.0"/>
  </joint>
  <joint name="panda_joint6" type="revolute">
    <parent link="panda_link5"/>
    <child link="panda_link6"/>
    <origin xyz="0.0 0.0 0.0" rpy="1.57079632679 -0.0 0.0"/>
    <axis xyz="0.0 0.0 1.0"/>
    <limit effort="12.0" velocity="2.61" lower="-0.0175" upper="3.7525"/>
    <dynamics damping="10.0"/>
  </joint>
  <joint name="panda_joint7" type="revolute">
    <parent link="panda_link6"/>
    <child link="panda_link7"/>
    <origin xyz="0.088 0.0 0.0" rpy="1.57079632679 -0.0 0.0"/>
    <axis xyz="0.0 0.0 1.0"/>
    <limit effort="12.0" velocity="2.61" lower="-2.8973" upper="2.8973"/>
    <dynamics damping="10.0"/>
  </joint>
  <joint name="panda_hand_joint" type="fixed">
    <parent link="panda_link7"/>
    <child link="panda_hand"/>
    <origin xyz="0.0 0.0 0.107" rpy="0.0 -0.0 -0.785398163397"/>
    <axis xyz="1.0 0.0 0.0"/>
  </joint>
  <joint name="panda_hand_tool_joint" type="fixed">
    <parent link="panda_hand"/>
    <child link="panda_tool"/>
    <origin xyz="0.0 0.0 0.1034" rpy="0.0 -0.0 0.0"/>
    <axis xyz="1.0 0.0 0.0"/>
  </joint>
  <joint name="panda_finger_joint1" type="fixed">
    <parent link="panda_hand"/>
    <child link="panda_leftfinger"/>
    <origin xyz="0.0 0.0 0.0584" rpy="0.0 -0.0 0.0"/>
    <axis xyz="0.0 1.0 0.0"/>
    <limit effort="20.0" velocity="0.2" lower="0.0" upper="0.04"/>
    <dynamics damping="10.0"/>
  </joint>
  <joint name="panda_finger_joint2" type="fixed">
    <parent link="panda_leftfinger"/>
    <child link="panda_rightfinger"/>
    <origin xyz="0.0 0.0 0.0" rpy="0.0 -0.0 0.0"/>
    <axis xyz="0.0 -1.0 0.0"/>
    <limit effort="20.0" velocity="0.2" lower="0.0" upper="0.04"/>
    <dynamics damping="10.0"/>
  </joint>
</robot>
